caught
No exception was raised
getCaught
start
cause
getCause
Thread
 in exception diagnostics.
sleep
Assert
assertTrue
assertNotNull
testInterruptedWaitForProxy
interrupt
join
worker
 no inner cause, use outer exception as root cause.
worker hasn't started
