Auth exception
Error while 
testWrapExceptionWithMessage
getMessage
assertEquals
getCause
 redirect the LOG to and check log message
ex
Assert
Error while authenticating with endpoint: localhost
KerberosAuthenticator
assertTrue
equals
authenticating with endpoint: localhost
wrapExceptionWithMessage
Induced exception
ex2
